<?xml version="1.0"?>
<!-- Basic URDF components for Jupiter2 Arm -->
<robot xmlns:xacro="http://ros.org/wiki/xacro">
  <xacro:property name="M_PI" value="3.14159265359"/>
  <xacro:property name="M_SCALE" value="0.001"/>
  <xacro:property name="F10_HEIGHT" value="0.004"/>
  <xacro:property name="F4_HEIGHT" value="0.0525"/>
  <xacro:property name="F3_HEIGHT" value="0.009"/>
  <xacro:property name="F2_HEIGHT" value="0.0265"/>
  <xacro:property name="AX12_HEIGHT" value="0.0385"/>
  <xacro:property name="AX12_WIDTH" value="0.038"/>
  <xacro:property name="AX12_LENGTH" value="0.050"/>

  <xacro:macro name="finger_active" params="parent name color *origin">
    <joint name="${name}_joint" type="fixed">
      <xacro:insert_block name="origin"/>
      <parent link="${parent}"/>
      <child link="${name}_link"/>
    </joint>

    <link name="${name}_link">
      <visual>
        <origin xyz="0 0 0" rpy="0 0 0"/>
        <geometry>
          <mesh filename="package://jupiterobot2_arm_description/meshes/finger_active.stl" scale="${M_SCALE} ${M_SCALE} ${M_SCALE}"/>
        </geometry>
        <material name="${color}"/>
      </visual>
      <collision>
        <origin xyz="0.0535 0.017 0.0105" rpy="0 0 0"/>
        <geometry>
          <box size="0.107 0.034 0.021"/>
        </geometry>
      </collision>
      <inertial>
        <origin xyz="0.0535 0.017 0.0105" rpy="0 0 0"/>
        <mass value="0.009"/>
        <inertia ixx="1.19775e-06" ixy="0" ixz="0"
                 iyy="8.9175e-06" iyz="0"
                 izz="9.45375e-06" />
      </inertial>
    </link>

    <gazebo reference="${name}_link">
      <material>Gazebo/${color}</material>
      <selfCollide>true</selfCollide>
      <gravity>true</gravity>
    </gazebo>
  </xacro:macro>

  <xacro:macro name="finger_fixed" params="parent name color *origin">
    <joint name="${name}_joint" type="fixed">
      <xacro:insert_block name="origin"/>
      <parent link="${parent}"/>
      <child link="${name}_link"/>
    </joint>

    <link name="${name}_link">
      <visual>
        <origin xyz="0 0 0" rpy="0 0 0"/>
        <geometry>
          <mesh filename="package://jupiterobot2_arm_description/meshes/finger_static.stl" scale="${M_SCALE} ${M_SCALE} ${M_SCALE}"/>
        </geometry>
        <material name="${color}"/>
      </visual>
      <collision>
        <origin xyz="0.045 0.017 0.0065" rpy="0 0 0"/>
        <geometry>
          <box size="0.09 0.034 0.013"/>
        </geometry>
      </collision>
      <inertial>
        <origin xyz="0.045 0.017 0.0065" rpy="0 0 0"/>
        <mass value="0.0075"/>
        <inertia ixx="8.28125e-07" ixy="0" ixz="0"
                 iyy="5.168125e-06" iyz="0"
                 izz="5.785e-06" />
      </inertial>
    </link>

    <gazebo reference="${name}_link">
      <material>Gazebo/${color}</material>
      <selfCollide>true</selfCollide>
      <gravity>true</gravity>
    </gazebo>
  </xacro:macro>

  <xacro:macro name="dynamixel_AX12_fixed" params="parent name *origin">
    <joint name="${name}_joint" type="fixed">
      <xacro:insert_block name="origin"/>
      <parent link="${parent}"/>
      <child link="${name}_link"/>
    </joint>

    <link name="${name}_link">
      <visual>
        <origin xyz="0 0 0" rpy="0 0 0"/>
        <geometry>
          <mesh filename="package://jupiterobot2_arm_description/meshes/ax12_box.stl" scale="${M_SCALE} ${M_SCALE} ${M_SCALE}"/>
        </geometry>
        <material name="Black"/>
      </visual>
      <collision>
        <origin xyz="0.0 0.0 -0.01241" rpy="0 0 0"/>
        <geometry>
          <box size="0.025 0.038 0.04762"/>
        </geometry>
      </collision>
      <inertial>
        <origin xyz="0 0 0"/>
        <mass value="0.055"/>
        <inertia ixx="0.000017012" ixy="0.0" ixz="0.0"
                 iyy="0.000013258" iyz="0.0"
                 izz="0.000009483"/>
      </inertial>
    </link>

    <gazebo reference="${name}_link">
      <material>Gazebo/Black</material>
      <selfCollide>true</selfCollide>
      <gravity>true</gravity>
    </gazebo>
  </xacro:macro>

  <xacro:macro name="bioloid_F10_fixed" params="parent name color *origin">
    <joint name="${name}_joint" type="fixed">
      <xacro:insert_block name="origin"/>
      <parent link="${parent}"/>
      <child link="${name}_link"/>
    </joint>

    <link name="${name}_link">
      <visual>
        <origin xyz="0 0 0" rpy="0 0 0"/>
        <geometry>
          <mesh filename="package://jupiterobot2_arm_description/meshes/F10.stl" scale="${M_SCALE} ${M_SCALE} ${M_SCALE}"/>
        </geometry>
        <material name="${color}"/>
      </visual>
      <collision>
        <origin xyz="0.0 0.0 0.0" rpy="0 0 0"/>
        <geometry>
          <box size="0.025 0.038 0.004"/>
        </geometry>
      </collision>
      <inertial>
        <origin xyz="0 0 0"/>  <!--0.025*0.038*0.004-->
        <mass value="0.0033"/>
        <inertia ixx="4.015e-07" ixy="0.0" ixz="0.0"
                 iyy="1.76275e-07" iyz="0.0"
                 izz="5.68975e-07"/>
      </inertial>
    </link>

    <gazebo reference="${name}_link">
      <material>Gazebo/${color}</material>
      <selfCollide>true</selfCollide>
      <gravity>true</gravity>
    </gazebo>
  </xacro:macro>

  <xacro:macro name="bioloid_F3_fixed" params="parent name color *origin">
    <joint name="${name}_joint" type="fixed">
      <xacro:insert_block name="origin"/>
      <parent link="${parent}"/>
      <child link="${name}_link"/>
    </joint>

    <link name="${name}_link">
      <visual>
        <origin xyz="0 0 0" rpy="0 0 0"/>
        <geometry>
          <mesh filename="package://jupiterobot2_arm_description/meshes/F3.stl" scale="${M_SCALE} ${M_SCALE} ${M_SCALE}"/>
        </geometry>
        <material name="${color}"/>
      </visual>
      <collision>
        <origin xyz="0.0 0.0 -0.0045" rpy="0 0 0"/>
        <geometry>
          <box size="0.025 0.038 0.009"/>
        </geometry>
      </collision>
      <inertial>
        <origin xyz="0 0 -0.004"/>  <!--0.025*0.038*0.008-->
        <mass value="0.005"/>
        <inertia ixx="6.2833e-07" ixy="0.0" ixz="0.0"
                 iyy="2.870833e-07" iyz="0.0"
                 izz="8.620833e-07"/>
      </inertial>
    </link>

    <gazebo reference="${name}_link">
      <material>Gazebo/${color}</material>
      <selfCollide>true</selfCollide>
      <gravity>true</gravity>
    </gazebo>
  </xacro:macro>

  <xacro:macro name="bioloid_F3_revolute" params="parent name color llimit ulimit vlimit *origin">
    <joint name="${name}_joint" type="revolute">
      <xacro:insert_block name="origin"/>
      <axis xyz="0 0 -1"/>
      <limit effort="30" velocity="${vlimit}" lower="${llimit}" upper="${ulimit}"/>
      <dynamics friction="0.13"/>
      <parent link="${parent}"/>
      <child link="${name}_link"/>
    </joint>

    <link name="${name}_link">
      <visual>
        <origin xyz="0 0 0" rpy="0 0 0"/>
        <geometry>
          <mesh filename="package://jupiterobot2_arm_description/meshes/F3.stl" scale="${M_SCALE} ${M_SCALE} ${M_SCALE}"/>
        </geometry>
        <material name="${color}"/>
      </visual>
      <collision>
        <origin xyz="0.0 0.0 -0.0045" rpy="0 0 0"/>
        <geometry>
          <box size="0.025 0.038 0.009"/>
        </geometry>
      </collision>
      <inertial>
        <origin xyz="0 0 -0.004"/>  <!--0.025*0.038*0.008-->
        <mass value="0.005"/>
        <inertia ixx="6.2833e-07" ixy="0.0" ixz="0.0"
                 iyy="2.870833e-07" iyz="0.0"
                 izz="8.620833e-07"/>
      </inertial>
    </link>

    <gazebo reference="${name}_link">
      <material>Gazebo/${color}</material>
      <selfCollide>true</selfCollide>
      <gravity>true</gravity>
    </gazebo>
  </xacro:macro>

  <xacro:macro name="bioloid_F2_revolute" params="parent name color llimit ulimit vlimit *origin">
    <joint name="${name}_joint" type="revolute">
      <xacro:insert_block name="origin"/>
      <axis xyz="0 1 0"/>
      <limit effort="30" velocity="${vlimit}" lower="${llimit}" upper="${ulimit}"/>
      <dynamics friction="0.13"/>
      <parent link="${parent}"/>
      <child link="${name}_link"/>
    </joint>

    <link name="${name}_link">
      <visual>
        <origin xyz="0 0 0" rpy="0 0 0"/>
        <geometry>
          <mesh filename="package://jupiterobot2_arm_description/meshes/F2.stl" scale="${M_SCALE} ${M_SCALE} ${M_SCALE}"/>
        </geometry>
        <material name="${color}"/>
      </visual>
      <collision>
        <origin xyz="0.0 0.0 0.00775" rpy="0 0 0"/>
        <geometry>
          <box size="0.025 0.0485 0.0375"/>
        </geometry>
      </collision>
      <inertial>
        <origin xyz="0 0 0.015"/>  <!--0.025*0.048*0.0375-->
        <mass value="0.0115"/>
        <inertia ixx="3.55565625e-06" ixy="0.0" ixz="0.0"
                 iyy="1.946614583e-06" iyz="0.0"
                 izz="2.80695833e-06"/>
      </inertial>
    </link>

    <gazebo reference="${name}_link">
      <material>Gazebo/${color}</material>
      <selfCollide>true</selfCollide>
      <gravity>true</gravity>
    </gazebo>
  </xacro:macro>

  <xacro:macro name="bioloid_F4_revolute" params="parent name color llimit ulimit vlimit *origin">
    <joint name="${name}_joint" type="revolute">
      <xacro:insert_block name="origin"/>
      <axis xyz="0 1 0"/>
      <limit effort="30" velocity="${vlimit}" lower="${llimit}" upper="${ulimit}"/>
      <dynamics friction="0.13"/>
      <parent link="${parent}"/>
      <child link="${name}_link"/>
    </joint>

    <link name="${name}_link">
      <visual>
        <origin xyz="0 0 0" rpy="0 0 0"/>
        <geometry>
          <mesh filename="package://jupiterobot2_arm_description/meshes/F4.stl" scale="${M_SCALE} ${M_SCALE} ${M_SCALE}"/>
        </geometry>
        <material name="${color}"/>
      </visual>
      <collision>
        <origin xyz="0.0 0.0 0.0215" rpy="0 0 0"/>
        <geometry>
          <box size="0.028 0.0485 0.065"/>
        </geometry>
      </collision>
      <inertial>
        <origin xyz="0 0 0.03"/>  <!--0.028*0.048*0.0635-->
        <mass value="0.019"/>
        <inertia ixx="1.003239583e-05" ixy="0.0" ixz="0.0"
                 iyy="7.625729167e-06" iyz="0.0"
                 izz="4.88933e-06"/>
      </inertial>
    </link>

    <gazebo reference="${name}_link">
      <material>Gazebo/${color}</material>
      <selfCollide>true</selfCollide>
      <gravity>true</gravity>
    </gazebo>
  </xacro:macro>

</robot>
