<?xml version="1.0" ?>
<!-- =================================================================================== -->
<!-- |    This document was autogenerated by xacro from /home/mustar/catkin_ws/src/jupiterobot2/jupiterobot2_description/urdf/jupiter2_lite.urdf.xacro | -->
<!-- |    EDITING THIS FILE BY HAND IS NOT RECOMMENDED                                 | -->
<!-- =================================================================================== -->
<robot name="jupiter2_lite">
    <!-- Init colour -->
    <material name="Black">
        <color rgba="0.0 0.0 0.0 1.0" />
    </material>
    <material name="FlatBlack">
        <color rgba="0.1 0.1 0.1 1.0" />
    </material>
    <material name="DarkGrey">
        <color rgba="0.3 0.3 0.3 1.0" />
    </material>
    <material name="Grey">
        <color rgba="0.5 0.5 0.5 1.0" />
    </material>
    <material name="Red">
        <color rgba="0.8 0.0 0.0 1.0" />
    </material>
    <material name="Green">
        <color rgba="0.0 0.8 0.0 1.0" />
    </material>
    <material name="Blue">
        <color rgba="0.0 0.0 0.8 1.0" />
    </material>
    <material name="White">
        <color rgba="1.0 1.0 1.0 1.0" />
    </material>
    <gazebo reference="base_link">
        <material>Gazebo/Black</material>
        <plugin name="gazebo_ros_control">
            <robotNamespace>/</robotNamespace>
        </plugin>
    </gazebo>
    <gazebo reference="wheel_left_link">
        <mu1>1</mu1>
        <mu2>1</mu2>
        <kp>1e6</kp>
        <kd>1e3</kd>
        <minDepth>0.001</minDepth>
        <maxVel>1</maxVel>
        <material>Gazebo/FlatBlack</material>
    </gazebo>
    <gazebo reference="wheel_right_link">
        <mu1>1</mu1>
        <mu2>1</mu2>
        <kp>1e6</kp>
        <kd>1e3</kd>
        <minDepth>0.001</minDepth>
        <maxVel>1</maxVel>
        <material>Gazebo/FlatBlack</material>
    </gazebo>
    <gazebo reference="caster_back_right_link">
        <mu1>0.01</mu1>
        <mu2>0.01</mu2>
        <kp>1e6</kp>
        <kd>1e3</kd>
        <minDepth>0.001</minDepth>
        <maxVel>1</maxVel>
        <material>Gazebo/Grey</material>
    </gazebo>
    <gazebo reference="caster_back_left_link">
        <mu1>0.01</mu1>
        <mu2>0.01</mu2>
        <kp>1e6</kp>
        <kd>1e3</kd>
        <minDepth>0.001</minDepth>
        <maxVel>1</maxVel>
        <material>Gazebo/Grey</material>
    </gazebo>
    <gazebo reference="imu_link">
        <sensor name="imu" type="imu">
            <always_on>true</always_on>
            <visualize>false</visualize>
        </sensor>
        <material>Gazebo/Grey</material>
    </gazebo>
    <gazebo reference="plate_1_link">
        <material>Gazebo/Black</material>
    </gazebo>
    <gazebo reference="plate_2_link">
        <material>Gazebo/Black</material>
    </gazebo>
    <gazebo reference="plate_3_link">
        <material>Gazebo/Black</material>
    </gazebo>
    <gazebo reference="arrow_link">
        <material>Gazebo/White</material>
    </gazebo>
    <gazebo reference="mic_link">
        <material>Gazebo/DarkGrey</material>
    </gazebo>
    <gazebo reference="estop_link">
        <material>Gazebo/DarkGrey</material>
    </gazebo>
    <gazebo reference="monitor_frame_1_link">
        <material>Gazebo/DarkGrey</material>
    </gazebo>
    <gazebo reference="monitor_frame_2_link">
        <material>Gazebo/DarkGrey</material>
    </gazebo>
    <gazebo reference="monitor_link">
        <material>Gazebo/FlatBlack</material>
    </gazebo>
    <gazebo reference="screen_link">
        <material>Gazebo/WhiteGlow</material>
    </gazebo>
    <gazebo reference="arm_mount_link">
        <material>Gazebo/DarkGrey</material>
    </gazebo>
    <gazebo reference="head_mount_link">
        <material>Gazebo/DarkGrey</material>
    </gazebo>
    <gazebo reference="pipe_200_link">
        <material>Gazebo/BlackTransparent</material>
    </gazebo>
    <gazebo reference="pipe_300_link">
        <material>Gazebo/BlackTransparent</material>
    </gazebo>
    <gazebo reference="cables_link">
        <material>Gazebo/BlackTransparent</material>
    </gazebo>
    <gazebo>
        <plugin filename="libgazebo_ros_diff_drive.so" name="jupiter2_controller">
            <commandTopic>cmd_vel</commandTopic>
            <odometryTopic>odom</odometryTopic>
            <odometryFrame>odom</odometryFrame>
            <odometrySource>world</odometrySource>
            <publishOdomTF>true</publishOdomTF>
            <robotBaseFrame>base_footprint</robotBaseFrame>
            <publishWheelTF>false</publishWheelTF>
            <publishTf>true</publishTf>
            <publishWheelJointState>true</publishWheelJointState>
            <legacyMode>false</legacyMode>
            <updateRate>30</updateRate>
            <leftJoint>wheel_left_joint</leftJoint>
            <rightJoint>wheel_right_joint</rightJoint>
            <wheelSeparation>0.287</wheelSeparation>
            <wheelDiameter>0.066</wheelDiameter>
            <wheelAcceleration>1</wheelAcceleration>
            <wheelTorque>10</wheelTorque>
            <rosDebugLevel>na</rosDebugLevel>
        </plugin>
    </gazebo>
    <gazebo>
        <plugin filename="libgazebo_ros_imu.so" name="imu_plugin">
            <alwaysOn>true</alwaysOn>
            <bodyName>imu_link</bodyName>
            <frameName>imu_link</frameName>
            <topicName>imu</topicName>
            <serviceName>imu_service</serviceName>
            <gaussianNoise>0.0</gaussianNoise>
            <updateRate>0</updateRate>
            <imu>
                <noise>
                    <type>gaussian</type>
                    <rate>
                        <mean>0.0</mean>
                        <stddev>2e-4</stddev>
                        <bias_mean>0.0000075</bias_mean>
                        <bias_stddev>0.0000008</bias_stddev>
                    </rate>
                    <accel>
                        <mean>0.0</mean>
                        <stddev>1.7e-2</stddev>
                        <bias_mean>0.1</bias_mean>
                        <bias_stddev>0.001</bias_stddev>
                    </accel>
                </noise>
            </imu>
        </plugin>
    </gazebo>
    <gazebo reference="base_scan">
        <material>Gazebo/FlatBlack</material>
        <sensor name="rplidar_a1_sensor" type="ray">
            <pose>0 0 0 0 0 0</pose>
            <visualize>false</visualize>
            <update_rate>5.5</update_rate>
            <ray>
                <scan>
                    <horizontal>
                        <samples>360</samples>
                        <resolution>1</resolution>
                        <min_angle>-3.14159265359</min_angle>
                        <max_angle>3.14159265359</max_angle>
                    </horizontal>
                </scan>
                <range>
                    <min>0.18</min>
                    <max>6.0</max>
                    <resolution>0.01</resolution>
                </range>
                <noise>
                    <type>gaussian</type>
                    <mean>0.0</mean>
                    <stddev>0.01</stddev>
                </noise>
            </ray>
            <plugin filename="libgazebo_ros_laser.so" name="gazebo_ros_rplidar_a1_controller">
                <topicName>scan</topicName>
                <frameName>base_scan</frameName>
            </plugin>
        </sensor>
    </gazebo>
    <gazebo reference="camera_link">
        <sensor name="camera" type="depth">
            <always_on>true</always_on>
            <visualize>false</visualize>
            <update_rate>20.0</update_rate>
            <camera>
                <horizontal_fov>1.0472</horizontal_fov>
                <image>
                    <width>640</width>
                    <height>480</height>
                    <format>R8G8B8</format>
                </image>
                <depth_camera />
                <clip>
                    <near>0.05</near>
                    <far>8.0</far>
                </clip>
            </camera>
            <plugin filename="libgazebo_ros_openni_kinect.so" name="camera_controller">
                <baseline>0.1</baseline>
                <alwaysOn>true</alwaysOn>
                <updateRate>20.0</updateRate>
                <cameraName>camera</cameraName>
                <frameName>camera_depth_optical_frame</frameName>
                <imageTopicName>color/image_raw</imageTopicName>
                <depthImageTopicName>depth/image_raw</depthImageTopicName>
                <pointCloudTopicName>depth/points</pointCloudTopicName>
                <cameraInfoTopicName>color/camera_info</cameraInfoTopicName>
                <depthImageCameraInfoTopicName>depth/camera_info</depthImageCameraInfoTopicName>
                <pointCloudCutoff>0.4</pointCloudCutoff>
                <hackBaseline>0.07</hackBaseline>
                <distortionK1>0.0</distortionK1>
                <distortionK2>0.0</distortionK2>
                <distortionK3>0.0</distortionK3>
                <distortionT1>0.0</distortionT1>
                <distortionT2>0.0</distortionT2>
                <CxPrime>0.0</CxPrime>
                <Cx>0.0</Cx>
                <Cy>0.0</Cy>
                <focalLength>0</focalLength>
                <hackBaseline>0</hackBaseline>
            </plugin>
        </sensor>
    </gazebo>
    <joint name="head_base_joint" type="fixed">
        <origin xyz="0.0 0.0 0.076" />
        <parent link="head_mount_link" />
        <child link="head_base_link" />
    </joint>
    <link name="head_base_link" />
    <joint name="head_servo_joint" type="fixed">
        <origin rpy="0 0 0" xyz="0 0 -0.041499999999999995" />
        <parent link="head_base_link" />
        <child link="head_servo_link" />
    </joint>
    <link name="head_servo_link">
        <visual>
            <origin rpy="0 0 0" xyz="0 0 0" />
            <geometry>
                <mesh filename="package://jupiterobot2_head_description/meshes/ax12_box.stl" scale="0.001 0.001 0.001" />
            </geometry>
            <material name="Black" />
        </visual>
        <collision>
            <origin rpy="0 0 0" xyz="0.0 0.0 -0.01241" />
            <geometry>
                <box size="0.025 0.038 0.04762" />
            </geometry>
        </collision>
        <inertial>
            <origin xyz="0 0 0" rpy="0 0 0" />
            <mass value="0.055" />
            <inertia ixx="0.000017012" ixy="0.0" ixz="0.0" iyy="0.000013258" iyz="0.0" izz="0.000009483" />
        </inertial>
    </link>
    <gazebo reference="head_servo_link">
        <material>Gazebo/Black</material>
        <selfCollide>true</selfCollide>
        <gravity>true</gravity>
    </gazebo>
    <joint name="head_joint" type="revolute">
        <origin rpy="0 0 0" xyz="0 0 0" />
        <axis xyz="0 1 0" />
        <limit effort="30" lower="-1.5" upper="1.5" velocity="1.571" />
        <dynamics friction="0.13" />
        <parent link="head_servo_link" />
        <child link="head_link" />
    </joint>
    <link name="head_link">
        <visual>
            <origin rpy="0 0 0" xyz="0 0 0" />
            <geometry>
                <mesh filename="package://jupiterobot2_head_description/meshes/F2.stl" scale="0.001 0.001 0.001" />
            </geometry>
            <material name="White" />
        </visual>
        <collision>
            <origin rpy="0 0 0" xyz="0.0 0.0 0.00775" />
            <geometry>
                <box size="0.025 0.0485 0.0375" />
            </geometry>
        </collision>
        <inertial>
            <origin xyz="0 0 0.015" rpy="0 0 0" />
            <!--0.025*0.048*0.0375-->
            <mass value="0.0115" />
            <inertia ixx="3.55565625e-06" ixy="0.0" ixz="0.0" iyy="1.946614583e-06" iyz="0.0" izz="2.80695833e-06" />
        </inertial>
    </link>
    <gazebo reference="head_link">
        <material>Gazebo/White</material>
        <selfCollide>true</selfCollide>
        <gravity>true</gravity>
    </gazebo>
    <joint name="head_plate_joint" type="fixed">
        <origin rpy="0 3.14159265359 0" xyz="0 0 0.0265" />
        <parent link="head_link" />
        <child link="head_plate_link" />
    </joint>
    <link name="head_plate_link">
        <visual>
            <origin rpy="0 0 0" xyz="0 0 0" />
            <geometry>
                <mesh filename="package://jupiterobot2_head_description/meshes/F3.stl" scale="0.001 0.001 0.001" />
            </geometry>
            <material name="White" />
        </visual>
        <collision>
            <origin rpy="0 0 0" xyz="0.0 0.0 -0.0045" />
            <geometry>
                <box size="0.025 0.038 0.009" />
            </geometry>
        </collision>
        <inertial>
            <origin xyz="0 0 -0.004" rpy="0 0 0" />
            <!--0.025*0.038*0.008-->
            <mass value="0.005" />
            <inertia ixx="6.2833e-07" ixy="0.0" ixz="0.0" iyy="2.870833e-07" iyz="0.0" izz="8.620833e-07" />
        </inertial>
    </link>
    <gazebo reference="head_plate_link">
        <material>Gazebo/White</material>
        <selfCollide>true</selfCollide>
        <gravity>true</gravity>
    </gazebo>
    <joint name="camera_joint" type="fixed">
        <origin rpy="0 3.14159265359 0" xyz="-0.0125 0 -0.0215" />
        <parent link="head_plate_link" />
        <child link="camera_link" />
    </joint>
    <link name="camera_link">
        <visual>
            <origin rpy="0 0 0" xyz="0 0 0" />
            <geometry>
                <mesh filename="package://jupiterobot2_head_description/meshes/camera.stl" scale="0.001 0.001 0.001" />
            </geometry>
            <material name="DarkGrey" />
        </visual>
        <collision>
            <origin rpy="0 0 0" xyz="-0.0125 0 0" />
            <geometry>
                <box size="0.025 0.109 0.025" />
            </geometry>
        </collision>
        <inertial>
            <origin rpy="0 0 0" xyz="-0.0125 0 0" />
            <mass value="0.06" />
            <inertia ixx="6.253e-05" ixy="0.0" ixz="0.0" iyy="6.25e-06" iyz="0.0" izz="6.253e-05" />
        </inertial>
    </link>
    <gazebo reference="camera_link">
        <material>Gazebo/DarkGrey</material>
        <selfCollide>true</selfCollide>
        <gravity>true</gravity>
    </gazebo>
    <joint name="camera_color_joint" type="fixed">
        <origin rpy="0 0 0" xyz="0.0 -0.009 0.0" />
        <parent link="camera_link" />
        <child link="camera_color_frame" />
    </joint>
    <link name="camera_color_frame" />
    <joint name="camera_color_optical_joint" type="fixed">
        <origin rpy="-1.570796326795 0 -1.570796326795" xyz="0 0 0" />
        <parent link="camera_color_frame" />
        <child link="camera_color_optical_frame" />
    </joint>
    <link name="camera_color_optical_frame" />
    <joint name="camera_depth_joint" type="fixed">
        <origin rpy="0 0 0" xyz="0.0 -0.008 0.0" />
        <parent link="camera_link" />
        <child link="camera_depth_frame" />
    </joint>
    <link name="camera_depth_frame" />
    <joint name="camera_depth_optical_joint" type="fixed">
        <origin rpy="-1.570796326795 0 -1.570796326795" xyz="0 0 0" />
        <parent link="camera_depth_frame" />
        <child link="camera_depth_optical_frame" />
    </joint>
    <link name="camera_depth_optical_frame" />
    <transmission name="tran6">
        <type>transmission_interface/SimpleTransmission</type>
        <joint name="head_joint">
            <hardwareInterface>hardware_interface/PositionJointInterface</hardwareInterface>
        </joint>
        <actuator name="motor6">
            <hardwareInterface>hardware_interface/PositionJointInterface</hardwareInterface>
            <mechanicalReduction>1</mechanicalReduction>
        </actuator>
    </transmission>
    <!-- ros_control plugin -->
    <!-- <gazebo>
    <plugin name="gazebo_ros_control" filename="libgazebo_ros_control.so">
      <controlPeriod>0.001</controlPeriod>
      <robotNamespace>/</robotNamespace>
      <robotSimType>gazebo_ros_control/DefaultRobotHWSim</robotSimType>
      <legacyModeNS>true</legacyModeNS>
    </plugin>
  </gazebo> -->
    <!-- As we don't have here a robot base, add a base_link link as its location reference -->
    <!--link name="arm_mount_link"/-->
    <link name="arm_base_link" />
    <joint name="arm_base_joint" type="fixed">
        <origin xyz="0.0 0.0 -0.015" />
        <parent link="arm_mount_link" />
        <child link="arm_base_link" />
    </joint>
    <joint name="arm1_servo_joint" type="fixed">
        <origin rpy="1.570796326795 0 1.570796326795" xyz="0 0 0" />
        <parent link="arm_base_link" />
        <child link="arm1_servo_link" />
    </joint>
    <link name="arm1_servo_link">
        <visual>
            <origin rpy="0 0 0" xyz="0 0 0" />
            <geometry>
                <mesh filename="package://jupiterobot2_arm_description/meshes/ax12_box.stl" scale="0.001 0.001 0.001" />
            </geometry>
            <material name="Black" />
        </visual>
        <collision>
            <origin rpy="0 0 0" xyz="0.0 0.0 -0.01241" />
            <geometry>
                <box size="0.025 0.038 0.04762" />
            </geometry>
        </collision>
        <inertial>
            <origin xyz="0 0 0" rpy="0 0 0" />
            <mass value="0.055" />
            <inertia ixx="0.000017012" ixy="0.0" ixz="0.0" iyy="0.000013258" iyz="0.0" izz="0.000009483" />
        </inertial>
    </link>
    <gazebo reference="arm1_servo_link">
        <material>Gazebo/Black</material>
        <selfCollide>true</selfCollide>
        <gravity>true</gravity>
    </gazebo>
    <joint name="arm1_joint" type="revolute">
        <origin rpy="-1.570796326795 1.570796326795 3.14159265359" xyz="0 0.019 0" />
        <axis xyz="0 0 -1" />
        <limit effort="30" lower="-2.617" upper="2.617" velocity="1.571" />
        <dynamics friction="0.13" />
        <parent link="arm1_servo_link" />
        <child link="arm1_link" />
    </joint>
    <link name="arm1_link">
        <visual>
            <origin rpy="0 0 0" xyz="0 0 0" />
            <geometry>
                <mesh filename="package://jupiterobot2_arm_description/meshes/F3.stl" scale="0.001 0.001 0.001" />
            </geometry>
            <material name="White" />
        </visual>
        <collision>
            <origin rpy="0 0 0" xyz="0.0 0.0 -0.0045" />
            <geometry>
                <box size="0.025 0.038 0.009" />
            </geometry>
        </collision>
        <inertial>
            <origin xyz="0 0 -0.004" rpy="0 0 0" />
            <!--0.025*0.038*0.008-->
            <mass value="0.005" />
            <inertia ixx="6.2833e-07" ixy="0.0" ixz="0.0" iyy="2.870833e-07" iyz="0.0" izz="8.620833e-07" />
        </inertial>
    </link>
    <gazebo reference="arm1_link">
        <material>Gazebo/White</material>
        <selfCollide>true</selfCollide>
        <gravity>true</gravity>
    </gazebo>
    <joint name="arm2_servo_joint" type="fixed">
        <origin rpy="0 3.14159265359 0" xyz="0 0 -0.041499999999999995" />
        <parent link="arm1_link" />
        <child link="arm2_servo_link" />
    </joint>
    <link name="arm2_servo_link">
        <visual>
            <origin rpy="0 0 0" xyz="0 0 0" />
            <geometry>
                <mesh filename="package://jupiterobot2_arm_description/meshes/ax12_box.stl" scale="0.001 0.001 0.001" />
            </geometry>
            <material name="Black" />
        </visual>
        <collision>
            <origin rpy="0 0 0" xyz="0.0 0.0 -0.01241" />
            <geometry>
                <box size="0.025 0.038 0.04762" />
            </geometry>
        </collision>
        <inertial>
            <origin xyz="0 0 0" rpy="0 0 0" />
            <mass value="0.055" />
            <inertia ixx="0.000017012" ixy="0.0" ixz="0.0" iyy="0.000013258" iyz="0.0" izz="0.000009483" />
        </inertial>
    </link>
    <gazebo reference="arm2_servo_link">
        <material>Gazebo/Black</material>
        <selfCollide>true</selfCollide>
        <gravity>true</gravity>
    </gazebo>
    <joint name="arm2_joint" type="revolute">
        <origin rpy="0 0 0" xyz="0 0 0" />
        <axis xyz="0 1 0" />
        <limit effort="30" lower="-2.617" upper="2.617" velocity="1.571" />
        <dynamics friction="0.13" />
        <parent link="arm2_servo_link" />
        <child link="arm2_link" />
    </joint>
    <link name="arm2_link">
        <visual>
            <origin rpy="0 0 0" xyz="0 0 0" />
            <geometry>
                <mesh filename="package://jupiterobot2_arm_description/meshes/F4.stl" scale="0.001 0.001 0.001" />
            </geometry>
            <material name="White" />
        </visual>
        <collision>
            <origin rpy="0 0 0" xyz="0.0 0.0 0.0215" />
            <geometry>
                <box size="0.028 0.0485 0.065" />
            </geometry>
        </collision>
        <inertial>
            <origin xyz="0 0 0.03" rpy="0 0 0" />
            <!--0.028*0.048*0.0635-->
            <mass value="0.019" />
            <inertia ixx="1.003239583e-05" ixy="0.0" ixz="0.0" iyy="7.625729167e-06" iyz="0.0" izz="4.88933e-06" />
        </inertial>
    </link>
    <gazebo reference="arm2_link">
        <material>Gazebo/White</material>
        <selfCollide>true</selfCollide>
        <gravity>true</gravity>
    </gazebo>
    <joint name="arm2_F10_1_joint" type="fixed">
        <origin rpy="0 0 0" xyz="0 0 0.0545" />
        <parent link="arm2_link" />
        <child link="arm2_F10_1_link" />
    </joint>
    <link name="arm2_F10_1_link">
        <visual>
            <origin rpy="0 0 0" xyz="0 0 0" />
            <geometry>
                <mesh filename="package://jupiterobot2_arm_description/meshes/F10.stl" scale="0.001 0.001 0.001" />
            </geometry>
            <material name="White" />
        </visual>
        <collision>
            <origin rpy="0 0 0" xyz="0.0 0.0 0.0" />
            <geometry>
                <box size="0.025 0.038 0.004" />
            </geometry>
        </collision>
        <inertial>
            <origin xyz="0 0 0" rpy="0 0 0" />
            <!--0.025*0.038*0.004-->
            <mass value="0.0033" />
            <inertia ixx="4.015e-07" ixy="0.0" ixz="0.0" iyy="1.76275e-07" iyz="0.0" izz="5.68975e-07" />
        </inertial>
    </link>
    <gazebo reference="arm2_F10_1_link">
        <material>Gazebo/White</material>
        <selfCollide>true</selfCollide>
        <gravity>true</gravity>
    </gazebo>
    <joint name="arm2_F10_2_joint" type="fixed">
        <origin rpy="0 0 0" xyz="0 0 0.004" />
        <parent link="arm2_F10_1_link" />
        <child link="arm2_F10_2_link" />
    </joint>
    <link name="arm2_F10_2_link">
        <visual>
            <origin rpy="0 0 0" xyz="0 0 0" />
            <geometry>
                <mesh filename="package://jupiterobot2_arm_description/meshes/F10.stl" scale="0.001 0.001 0.001" />
            </geometry>
            <material name="White" />
        </visual>
        <collision>
            <origin rpy="0 0 0" xyz="0.0 0.0 0.0" />
            <geometry>
                <box size="0.025 0.038 0.004" />
            </geometry>
        </collision>
        <inertial>
            <origin xyz="0 0 0" rpy="0 0 0" />
            <!--0.025*0.038*0.004-->
            <mass value="0.0033" />
            <inertia ixx="4.015e-07" ixy="0.0" ixz="0.0" iyy="1.76275e-07" iyz="0.0" izz="5.68975e-07" />
        </inertial>
    </link>
    <gazebo reference="arm2_F10_2_link">
        <material>Gazebo/White</material>
        <selfCollide>true</selfCollide>
        <gravity>true</gravity>
    </gazebo>
    <joint name="arm2_F10_3_joint" type="fixed">
        <origin rpy="0 0 0" xyz="0 0 0.004" />
        <parent link="arm2_F10_2_link" />
        <child link="arm2_F10_3_link" />
    </joint>
    <link name="arm2_F10_3_link">
        <visual>
            <origin rpy="0 0 0" xyz="0 0 0" />
            <geometry>
                <mesh filename="package://jupiterobot2_arm_description/meshes/F10.stl" scale="0.001 0.001 0.001" />
            </geometry>
            <material name="White" />
        </visual>
        <collision>
            <origin rpy="0 0 0" xyz="0.0 0.0 0.0" />
            <geometry>
                <box size="0.025 0.038 0.004" />
            </geometry>
        </collision>
        <inertial>
            <origin xyz="0 0 0" rpy="0 0 0" />
            <!--0.025*0.038*0.004-->
            <mass value="0.0033" />
            <inertia ixx="4.015e-07" ixy="0.0" ixz="0.0" iyy="1.76275e-07" iyz="0.0" izz="5.68975e-07" />
        </inertial>
    </link>
    <gazebo reference="arm2_F10_3_link">
        <material>Gazebo/White</material>
        <selfCollide>true</selfCollide>
        <gravity>true</gravity>
    </gazebo>
    <joint name="arm2_F3_joint" type="fixed">
        <origin rpy="0 3.14159265359 0" xyz="0 0 0.002" />
        <parent link="arm2_F10_3_link" />
        <child link="arm2_F3_link" />
    </joint>
    <link name="arm2_F3_link">
        <visual>
            <origin rpy="0 0 0" xyz="0 0 0" />
            <geometry>
                <mesh filename="package://jupiterobot2_arm_description/meshes/F3.stl" scale="0.001 0.001 0.001" />
            </geometry>
            <material name="White" />
        </visual>
        <collision>
            <origin rpy="0 0 0" xyz="0.0 0.0 -0.0045" />
            <geometry>
                <box size="0.025 0.038 0.009" />
            </geometry>
        </collision>
        <inertial>
            <origin xyz="0 0 -0.004" rpy="0 0 0" />
            <!--0.025*0.038*0.008-->
            <mass value="0.005" />
            <inertia ixx="6.2833e-07" ixy="0.0" ixz="0.0" iyy="2.870833e-07" iyz="0.0" izz="8.620833e-07" />
        </inertial>
    </link>
    <gazebo reference="arm2_F3_link">
        <material>Gazebo/White</material>
        <selfCollide>true</selfCollide>
        <gravity>true</gravity>
    </gazebo>
    <joint name="arm3_servo_joint" type="fixed">
        <origin rpy="0 3.14159265359 0" xyz="0 0 -0.041499999999999995" />
        <parent link="arm2_F3_link" />
        <child link="arm3_servo_link" />
    </joint>
    <link name="arm3_servo_link">
        <visual>
            <origin rpy="0 0 0" xyz="0 0 0" />
            <geometry>
                <mesh filename="package://jupiterobot2_arm_description/meshes/ax12_box.stl" scale="0.001 0.001 0.001" />
            </geometry>
            <material name="Black" />
        </visual>
        <collision>
            <origin rpy="0 0 0" xyz="0.0 0.0 -0.01241" />
            <geometry>
                <box size="0.025 0.038 0.04762" />
            </geometry>
        </collision>
        <inertial>
            <origin xyz="0 0 0" rpy="0 0 0" />
            <mass value="0.055" />
            <inertia ixx="0.000017012" ixy="0.0" ixz="0.0" iyy="0.000013258" iyz="0.0" izz="0.000009483" />
        </inertial>
    </link>
    <gazebo reference="arm3_servo_link">
        <material>Gazebo/Black</material>
        <selfCollide>true</selfCollide>
        <gravity>true</gravity>
    </gazebo>
    <joint name="arm3_joint" type="revolute">
        <origin rpy="0 0 0" xyz="0 0 0" />
        <axis xyz="0 1 0" />
        <limit effort="30" lower="-2.617" upper="2.617" velocity="1.571" />
        <dynamics friction="0.13" />
        <parent link="arm3_servo_link" />
        <child link="arm3_link" />
    </joint>
    <link name="arm3_link">
        <visual>
            <origin rpy="0 0 0" xyz="0 0 0" />
            <geometry>
                <mesh filename="package://jupiterobot2_arm_description/meshes/F4.stl" scale="0.001 0.001 0.001" />
            </geometry>
            <material name="White" />
        </visual>
        <collision>
            <origin rpy="0 0 0" xyz="0.0 0.0 0.0215" />
            <geometry>
                <box size="0.028 0.0485 0.065" />
            </geometry>
        </collision>
        <inertial>
            <origin xyz="0 0 0.03" rpy="0 0 0" />
            <!--0.028*0.048*0.0635-->
            <mass value="0.019" />
            <inertia ixx="1.003239583e-05" ixy="0.0" ixz="0.0" iyy="7.625729167e-06" iyz="0.0" izz="4.88933e-06" />
        </inertial>
    </link>
    <gazebo reference="arm3_link">
        <material>Gazebo/White</material>
        <selfCollide>true</selfCollide>
        <gravity>true</gravity>
    </gazebo>
    <joint name="arm3_F10_1_joint" type="fixed">
        <origin rpy="0 0 0" xyz="0 0 0.0545" />
        <parent link="arm3_link" />
        <child link="arm3_F10_1_link" />
    </joint>
    <link name="arm3_F10_1_link">
        <visual>
            <origin rpy="0 0 0" xyz="0 0 0" />
            <geometry>
                <mesh filename="package://jupiterobot2_arm_description/meshes/F10.stl" scale="0.001 0.001 0.001" />
            </geometry>
            <material name="White" />
        </visual>
        <collision>
            <origin rpy="0 0 0" xyz="0.0 0.0 0.0" />
            <geometry>
                <box size="0.025 0.038 0.004" />
            </geometry>
        </collision>
        <inertial>
            <origin xyz="0 0 0" rpy="0 0 0" />
            <!--0.025*0.038*0.004-->
            <mass value="0.0033" />
            <inertia ixx="4.015e-07" ixy="0.0" ixz="0.0" iyy="1.76275e-07" iyz="0.0" izz="5.68975e-07" />
        </inertial>
    </link>
    <gazebo reference="arm3_F10_1_link">
        <material>Gazebo/White</material>
        <selfCollide>true</selfCollide>
        <gravity>true</gravity>
    </gazebo>
    <joint name="arm3_F10_2_joint" type="fixed">
        <origin rpy="0 0 0" xyz="0 0 0.004" />
        <parent link="arm3_F10_1_link" />
        <child link="arm3_F10_2_link" />
    </joint>
    <link name="arm3_F10_2_link">
        <visual>
            <origin rpy="0 0 0" xyz="0 0 0" />
            <geometry>
                <mesh filename="package://jupiterobot2_arm_description/meshes/F10.stl" scale="0.001 0.001 0.001" />
            </geometry>
            <material name="White" />
        </visual>
        <collision>
            <origin rpy="0 0 0" xyz="0.0 0.0 0.0" />
            <geometry>
                <box size="0.025 0.038 0.004" />
            </geometry>
        </collision>
        <inertial>
            <origin xyz="0 0 0" rpy="0 0 0" />
            <!--0.025*0.038*0.004-->
            <mass value="0.0033" />
            <inertia ixx="4.015e-07" ixy="0.0" ixz="0.0" iyy="1.76275e-07" iyz="0.0" izz="5.68975e-07" />
        </inertial>
    </link>
    <gazebo reference="arm3_F10_2_link">
        <material>Gazebo/White</material>
        <selfCollide>true</selfCollide>
        <gravity>true</gravity>
    </gazebo>
    <joint name="arm3_F10_3_joint" type="fixed">
        <origin rpy="0 0 0" xyz="0 0 0.004" />
        <parent link="arm3_F10_2_link" />
        <child link="arm3_F10_3_link" />
    </joint>
    <link name="arm3_F10_3_link">
        <visual>
            <origin rpy="0 0 0" xyz="0 0 0" />
            <geometry>
                <mesh filename="package://jupiterobot2_arm_description/meshes/F10.stl" scale="0.001 0.001 0.001" />
            </geometry>
            <material name="White" />
        </visual>
        <collision>
            <origin rpy="0 0 0" xyz="0.0 0.0 0.0" />
            <geometry>
                <box size="0.025 0.038 0.004" />
            </geometry>
        </collision>
        <inertial>
            <origin xyz="0 0 0" rpy="0 0 0" />
            <!--0.025*0.038*0.004-->
            <mass value="0.0033" />
            <inertia ixx="4.015e-07" ixy="0.0" ixz="0.0" iyy="1.76275e-07" iyz="0.0" izz="5.68975e-07" />
        </inertial>
    </link>
    <gazebo reference="arm3_F10_3_link">
        <material>Gazebo/White</material>
        <selfCollide>true</selfCollide>
        <gravity>true</gravity>
    </gazebo>
    <joint name="arm3_F3_joint" type="fixed">
        <origin rpy="0 3.14159265359 0" xyz="0 0 0.002" />
        <parent link="arm3_F10_3_link" />
        <child link="arm3_F3_link" />
    </joint>
    <link name="arm3_F3_link">
        <visual>
            <origin rpy="0 0 0" xyz="0 0 0" />
            <geometry>
                <mesh filename="package://jupiterobot2_arm_description/meshes/F3.stl" scale="0.001 0.001 0.001" />
            </geometry>
            <material name="White" />
        </visual>
        <collision>
            <origin rpy="0 0 0" xyz="0.0 0.0 -0.0045" />
            <geometry>
                <box size="0.025 0.038 0.009" />
            </geometry>
        </collision>
        <inertial>
            <origin xyz="0 0 -0.004" rpy="0 0 0" />
            <!--0.025*0.038*0.008-->
            <mass value="0.005" />
            <inertia ixx="6.2833e-07" ixy="0.0" ixz="0.0" iyy="2.870833e-07" iyz="0.0" izz="8.620833e-07" />
        </inertial>
    </link>
    <gazebo reference="arm3_F3_link">
        <material>Gazebo/White</material>
        <selfCollide>true</selfCollide>
        <gravity>true</gravity>
    </gazebo>
    <joint name="arm4_servo_joint" type="fixed">
        <origin rpy="0 3.14159265359 0" xyz="0 0 -0.041499999999999995" />
        <parent link="arm3_F3_link" />
        <child link="arm4_servo_link" />
    </joint>
    <link name="arm4_servo_link">
        <visual>
            <origin rpy="0 0 0" xyz="0 0 0" />
            <geometry>
                <mesh filename="package://jupiterobot2_arm_description/meshes/ax12_box.stl" scale="0.001 0.001 0.001" />
            </geometry>
            <material name="Black" />
        </visual>
        <collision>
            <origin rpy="0 0 0" xyz="0.0 0.0 -0.01241" />
            <geometry>
                <box size="0.025 0.038 0.04762" />
            </geometry>
        </collision>
        <inertial>
            <origin xyz="0 0 0" rpy="0 0 0" />
            <mass value="0.055" />
            <inertia ixx="0.000017012" ixy="0.0" ixz="0.0" iyy="0.000013258" iyz="0.0" izz="0.000009483" />
        </inertial>
    </link>
    <gazebo reference="arm4_servo_link">
        <material>Gazebo/Black</material>
        <selfCollide>true</selfCollide>
        <gravity>true</gravity>
    </gazebo>
    <joint name="arm4_joint" type="revolute">
        <origin rpy="0 0 0" xyz="0 0 0" />
        <axis xyz="0 1 0" />
        <limit effort="30" lower="-1.745" upper="1.745" velocity="1.571" />
        <dynamics friction="0.13" />
        <parent link="arm4_servo_link" />
        <child link="arm4_link" />
    </joint>
    <link name="arm4_link">
        <visual>
            <origin rpy="0 0 0" xyz="0 0 0" />
            <geometry>
                <mesh filename="package://jupiterobot2_arm_description/meshes/F2.stl" scale="0.001 0.001 0.001" />
            </geometry>
            <material name="White" />
        </visual>
        <collision>
            <origin rpy="0 0 0" xyz="0.0 0.0 0.00775" />
            <geometry>
                <box size="0.025 0.0485 0.0375" />
            </geometry>
        </collision>
        <inertial>
            <origin xyz="0 0 0.015" rpy="0 0 0" />
            <!--0.025*0.048*0.0375-->
            <mass value="0.0115" />
            <inertia ixx="3.55565625e-06" ixy="0.0" ixz="0.0" iyy="1.946614583e-06" iyz="0.0" izz="2.80695833e-06" />
        </inertial>
    </link>
    <gazebo reference="arm4_link">
        <material>Gazebo/White</material>
        <selfCollide>true</selfCollide>
        <gravity>true</gravity>
    </gazebo>
    <!-- fake gripper_link joint gives us a free servo!
         this makes us 5DOF and saves you $44.90
         that's a lot of coin! -->
    <link name="gripper_link" />
    <joint name="gripper_link_joint" type="revolute">
        <origin rpy="0 -1.57 0" xyz="0 0 0.112" />
        <parent link="arm4_link" />
        <child link="gripper_link" />
        <limit effort="30" lower="-3.14" upper="3.14" velocity="1" />
        <axis xyz="1 0 0" />
    </joint>
    <joint name="arm4_F3_joint" type="fixed">
        <origin rpy="0 3.14159265359 -1.570796326795" xyz="0 0.016 0.0265" />
        <parent link="arm4_link" />
        <child link="arm4_F3_link" />
    </joint>
    <link name="arm4_F3_link">
        <visual>
            <origin rpy="0 0 0" xyz="0 0 0" />
            <geometry>
                <mesh filename="package://jupiterobot2_arm_description/meshes/F3.stl" scale="0.001 0.001 0.001" />
            </geometry>
            <material name="White" />
        </visual>
        <collision>
            <origin rpy="0 0 0" xyz="0.0 0.0 -0.0045" />
            <geometry>
                <box size="0.025 0.038 0.009" />
            </geometry>
        </collision>
        <inertial>
            <origin xyz="0 0 -0.004" rpy="0 0 0" />
            <!--0.025*0.038*0.008-->
            <mass value="0.005" />
            <inertia ixx="6.2833e-07" ixy="0.0" ixz="0.0" iyy="2.870833e-07" iyz="0.0" izz="8.620833e-07" />
        </inertial>
    </link>
    <gazebo reference="arm4_F3_link">
        <material>Gazebo/White</material>
        <selfCollide>true</selfCollide>
        <gravity>true</gravity>
    </gazebo>
    <joint name="gripper_servo_joint" type="fixed">
        <origin rpy="3.14159265359 1.570796326795 0" xyz="-0.02275 0 -0.019" />
        <parent link="arm4_F3_link" />
        <child link="gripper_servo_link" />
    </joint>
    <link name="gripper_servo_link">
        <visual>
            <origin rpy="0 0 0" xyz="0 0 0" />
            <geometry>
                <mesh filename="package://jupiterobot2_arm_description/meshes/ax12_box.stl" scale="0.001 0.001 0.001" />
            </geometry>
            <material name="Black" />
        </visual>
        <collision>
            <origin rpy="0 0 0" xyz="0.0 0.0 -0.01241" />
            <geometry>
                <box size="0.025 0.038 0.04762" />
            </geometry>
        </collision>
        <inertial>
            <origin xyz="0 0 0" rpy="0 0 0" />
            <mass value="0.055" />
            <inertia ixx="0.000017012" ixy="0.0" ixz="0.0" iyy="0.000013258" iyz="0.0" izz="0.000009483" />
        </inertial>
    </link>
    <gazebo reference="gripper_servo_link">
        <material>Gazebo/Black</material>
        <selfCollide>true</selfCollide>
        <gravity>true</gravity>
    </gazebo>
    <!-- finger 1 -->
    <joint name="gripper_joint" type="revolute">
        <origin rpy="0 0 0" xyz="0 0 0" />
        <axis xyz="0 1 0" />
        <limit effort="30" lower="-0.40" upper="0.46" velocity="0.785" />
        <parent link="gripper_servo_link" />
        <child link="gripper_active_link" />
    </joint>
    <link name="gripper_active_link">
        <inertial>
            <mass value="0.010" />
            <origin xyz="0 0 0" rpy="0 0 0" />
            <inertia ixx="0.000001" ixy="0.0" ixz="0.0" iyy="0.000001" iyz="0.0" izz="0.000001" />
        </inertial>
        <visual>
            <origin rpy="0 0 0" xyz="0 0 0" />
            <geometry>
                <mesh filename="package://jupiterobot2_arm_description/meshes/F2.stl" scale="0.001 0.001 0.001" />
            </geometry>
            <material name="White" />
        </visual>
        <collision>
            <origin rpy="0 0 0" xyz="0.0 0.0 0.00775" />
            <geometry>
                <box size="0.025 0.0485 0.0375" />
            </geometry>
        </collision>
    </link>
    <joint name="gripper_active_finger_joint" type="fixed">
        <origin rpy="3.14159265359 0 0" xyz="-0.013 0.017 0.0295" />
        <parent link="gripper_active_link" />
        <child link="gripper_active_finger_link" />
    </joint>
    <link name="gripper_active_finger_link">
        <visual>
            <origin rpy="0 0 0" xyz="0 0 0" />
            <geometry>
                <mesh filename="package://jupiterobot2_arm_description/meshes/finger_active.stl" scale="0.001 0.001 0.001" />
            </geometry>
            <material name="Black" />
        </visual>
        <collision>
            <origin rpy="0 0 0" xyz="0.0535 0.017 0.0105" />
            <geometry>
                <box size="0.107 0.034 0.021" />
            </geometry>
        </collision>
        <inertial>
            <origin rpy="0 0 0" xyz="0.0535 0.017 0.0105" />
            <mass value="0.009" />
            <inertia ixx="1.19775e-06" ixy="0" ixz="0" iyy="8.9175e-06" iyz="0" izz="9.45375e-06" />
        </inertial>
    </link>
    <gazebo reference="gripper_active_finger_link">
        <material>Gazebo/Black</material>
        <selfCollide>true</selfCollide>
        <gravity>true</gravity>
    </gazebo>
    <joint name="gripper_static_joint" type="fixed">
        <origin rpy="0 3.14159265359 0" xyz="0 0 -0.041499999999999995" />
        <parent link="gripper_servo_link" />
        <child link="gripper_static_link" />
    </joint>
    <link name="gripper_static_link">
        <visual>
            <origin rpy="0 0 0" xyz="0 0 0" />
            <geometry>
                <mesh filename="package://jupiterobot2_arm_description/meshes/F3.stl" scale="0.001 0.001 0.001" />
            </geometry>
            <material name="White" />
        </visual>
        <collision>
            <origin rpy="0 0 0" xyz="0.0 0.0 -0.0045" />
            <geometry>
                <box size="0.025 0.038 0.009" />
            </geometry>
        </collision>
        <inertial>
            <origin xyz="0 0 -0.004" rpy="0 0 0" />
            <!--0.025*0.038*0.008-->
            <mass value="0.005" />
            <inertia ixx="6.2833e-07" ixy="0.0" ixz="0.0" iyy="2.870833e-07" iyz="0.0" izz="8.620833e-07" />
        </inertial>
    </link>
    <gazebo reference="gripper_static_link">
        <material>Gazebo/White</material>
        <selfCollide>true</selfCollide>
        <gravity>true</gravity>
    </gazebo>
    <joint name="gripper_static_finger_joint" type="fixed">
        <origin rpy="0 0 3.14159265359" xyz="0.013 0.017 0" />
        <parent link="gripper_static_link" />
        <child link="gripper_static_finger_link" />
    </joint>
    <link name="gripper_static_finger_link">
        <visual>
            <origin rpy="0 0 0" xyz="0 0 0" />
            <geometry>
                <mesh filename="package://jupiterobot2_arm_description/meshes/finger_static.stl" scale="0.001 0.001 0.001" />
            </geometry>
            <material name="Black" />
        </visual>
        <collision>
            <origin rpy="0 0 0" xyz="0.045 0.017 0.0065" />
            <geometry>
                <box size="0.09 0.034 0.013" />
            </geometry>
        </collision>
        <inertial>
            <origin rpy="0 0 0" xyz="0.045 0.017 0.0065" />
            <mass value="0.0075" />
            <inertia ixx="8.28125e-07" ixy="0" ixz="0" iyy="5.168125e-06" iyz="0" izz="5.785e-06" />
        </inertial>
    </link>
    <gazebo reference="gripper_static_finger_link">
        <material>Gazebo/Black</material>
        <selfCollide>true</selfCollide>
        <gravity>true</gravity>
    </gazebo>
    <transmission name="tran1">
        <type>transmission_interface/SimpleTransmission</type>
        <joint name="arm1_joint">
            <hardwareInterface>hardware_interface/PositionJointInterface</hardwareInterface>
        </joint>
        <actuator name="motor1">
            <hardwareInterface>hardware_interface/PositionJointInterface</hardwareInterface>
            <mechanicalReduction>1</mechanicalReduction>
        </actuator>
    </transmission>
    <transmission name="tran2">
        <type>transmission_interface/SimpleTransmission</type>
        <joint name="arm2_joint">
            <hardwareInterface>hardware_interface/PositionJointInterface</hardwareInterface>
        </joint>
        <actuator name="motor2">
            <hardwareInterface>hardware_interface/PositionJointInterface</hardwareInterface>
            <mechanicalReduction>1</mechanicalReduction>
        </actuator>
    </transmission>
    <transmission name="tran3">
        <type>transmission_interface/SimpleTransmission</type>
        <joint name="arm3_joint">
            <hardwareInterface>hardware_interface/PositionJointInterface</hardwareInterface>
        </joint>
        <actuator name="motor3">
            <hardwareInterface>hardware_interface/PositionJointInterface</hardwareInterface>
            <mechanicalReduction>1</mechanicalReduction>
        </actuator>
    </transmission>
    <transmission name="tran4">
        <type>transmission_interface/SimpleTransmission</type>
        <joint name="arm4_joint">
            <hardwareInterface>hardware_interface/PositionJointInterface</hardwareInterface>
        </joint>
        <actuator name="motor4">
            <hardwareInterface>hardware_interface/PositionJointInterface</hardwareInterface>
            <mechanicalReduction>1</mechanicalReduction>
        </actuator>
    </transmission>
    <transmission name="tran5">
        <type>transmission_interface/SimpleTransmission</type>
        <joint name="gripper_joint">
            <hardwareInterface>hardware_interface/PositionJointInterface</hardwareInterface>
        </joint>
        <actuator name="motor5">
            <hardwareInterface>hardware_interface/PositionJointInterface</hardwareInterface>
            <mechanicalReduction>1</mechanicalReduction>
        </actuator>
    </transmission>
    <!-- ros_control plugin -->
    <gazebo>
        <plugin filename="libgazebo_ros_control.so" name="gazebo_ros_control">
            <controlPeriod>0.001</controlPeriod>
            <robotNamespace>/</robotNamespace>
            <robotSimType>gazebo_ros_control/DefaultRobotHWSim</robotSimType>
            <legacyModeNS>true</legacyModeNS>
        </plugin>
    </gazebo>
    <link name="base_footprint" />
    <joint name="base_joint" type="fixed">
        <parent link="base_footprint" />
        <child link="base_link" />
        <origin rpy="0 0 0" xyz="0 0 0.015" />
    </joint>
    <link name="base_link">
        <visual>
            <origin rpy="0 0 0" xyz="-0.089 0 0" />
            <geometry>
                <mesh filename="package://jupiterobot2_description/meshes/stacks/jupiter2_base.stl" scale="0.001 0.001 0.001" />
            </geometry>
            <material name="Black" />
        </visual>
        <collision>
            <origin rpy="0 0 0" xyz="-0.089 0 0.039" />
            <geometry>
                <box size="0.33 0.33 0.078" />
            </geometry>
        </collision>
        <inertial>
            <origin rpy="0 0 0" xyz="-0.089 0 0.039" />
            <mass value="4.6" />
            <inertia ixx="0.0440772" ixy="0" ixz="0" iyy="0.0440772" iyz="0" izz="0.08349" />
        </inertial>
    </link>
    <joint name="wheel_left_joint" type="continuous">
        <parent link="base_link" />
        <child link="wheel_left_link" />
        <origin rpy="-1.570796326795 0 0" xyz="0.0 0.144 0.018" />
        <axis xyz="0 0 1" />
    </joint>
    <link name="wheel_left_link">
        <visual>
            <origin rpy="1.570796326795 0 0" xyz="0 0 0" />
            <geometry>
                <mesh filename="package://jupiterobot2_description/meshes/wheels/left_tire.stl" scale="0.001 0.001 0.001" />
            </geometry>
            <material name="FlatBlack" />
        </visual>
        <collision>
            <origin rpy="0 0 0" xyz="0 0 0" />
            <geometry>
                <cylinder length="0.018" radius="0.033" />
            </geometry>
        </collision>
        <inertial>
            <origin xyz="0 0 0" rpy="0 0 0" />
            <mass value="0.03" />
            <inertia ixx="9e-06" ixy="0.0" ixz="0.0" iyy="9e-06" iyz="0.0" izz="1.64e-05" />
        </inertial>
    </link>
    <joint name="wheel_right_joint" type="continuous">
        <parent link="base_link" />
        <child link="wheel_right_link" />
        <origin rpy="-1.570796326795 0 0" xyz="0.0 -0.144 0.018" />
        <axis xyz="0 0 1" />
    </joint>
    <link name="wheel_right_link">
        <visual>
            <origin rpy="1.570796326795 0 0" xyz="0 0 0" />
            <geometry>
                <mesh filename="package://jupiterobot2_description/meshes/wheels/right_tire.stl" scale="0.001 0.001 0.001" />
            </geometry>
            <material name="FlatBlack" />
        </visual>
        <collision>
            <origin rpy="0 0 0" xyz="0 0 0" />
            <geometry>
                <cylinder length="0.018" radius="0.033" />
            </geometry>
        </collision>
        <inertial>
            <origin xyz="0 0 0" rpy="0 0 0" />
            <mass value="0.03" />
            <inertia ixx="9e-06" ixy="0.0" ixz="0.0" iyy="9e-06" iyz="0.0" izz="1.64e-05" />
        </inertial>
    </link>
    <joint name="caster_back_right_joint" type="fixed">
        <parent link="base_link" />
        <child link="caster_back_right_link" />
        <origin rpy="-1.570796326795 0 0" xyz="-0.177 -0.064 -0.0025" />
    </joint>
    <link name="caster_back_right_link">
        <visual>
            <origin rpy="0 0 0" xyz="0 0 0" />
            <geometry>
                <mesh filename="package://jupiterobot2_description/meshes/wheels/caster.stl" scale="0.001 0.001 0.001" />
            </geometry>
            <material name="Grey" />
        </visual>
        <collision>
            <origin rpy="0 0 0" xyz="0 0 0" />
            <geometry>
                <sphere radius="0.0125" />
            </geometry>
        </collision>
        <inertial>
            <origin xyz="0 0 0" rpy="0 0 0" />
            <mass value="0.065" />
            <!--2/5*m*r^2-->
            <inertia ixx="4.0625e-06" ixy="0.0" ixz="0.0" iyy="4.0625e-06" iyz="0.0" izz="4.0625e-06" />
        </inertial>
    </link>
    <joint name="caster_back_left_joint" type="fixed">
        <parent link="base_link" />
        <child link="caster_back_left_link" />
        <origin rpy="-1.570796326795 0 0" xyz="-0.177 0.064 -0.0025" />
    </joint>
    <link name="caster_back_left_link">
        <visual>
            <origin rpy="0 0 0" xyz="0 0 0" />
            <geometry>
                <mesh filename="package://jupiterobot2_description/meshes/wheels/caster.stl" scale="0.001 0.001 0.001" />
            </geometry>
            <material name="Grey" />
        </visual>
        <collision>
            <origin rpy="0 0 0" xyz="0 0 0" />
            <geometry>
                <sphere radius="0.0125" />
            </geometry>
        </collision>
        <inertial>
            <origin xyz="0 0 0" rpy="0 0 0" />
            <mass value="0.065" />
            <!--2/5*m*r^2-->
            <inertia ixx="4.0625e-06" ixy="0.0" ixz="0.0" iyy="4.0625e-06" iyz="0.0" izz="4.0625e-06" />
        </inertial>
    </link>
    <joint name="imu_joint" type="fixed">
        <parent link="base_link" />
        <child link="imu_link" />
        <origin rpy="3.14159265359 0 0" xyz="-0.091 -0.1055 0.0535" />
    </joint>
    <link name="imu_link" />
    <!-- base link for stacks -->
    <joint name="stack_joint" type="fixed">
        <parent link="base_link" />
        <child link="stack_link" />
        <origin rpy="0 0 0" xyz="-0.089 0 0" />
    </joint>
    <link name="stack_link" />
    <joint name="pole_60_0_joint" type="fixed">
        <parent link="stack_link" />
        <child link="pole_60_0_link" />
        <origin rpy="0 0 0" xyz="0.06 0.116 0.108" />
    </joint>
    <link name="pole_60_0_link">
        <visual>
            <origin rpy="0 0 0" xyz="0 0 0" />
            <geometry>
                <mesh filename="package://jupiterobot2_description/meshes/stacks/pole_60.stl" scale="0.001 0.001 0.001" />
            </geometry>
            <material name="Grey" />
        </visual>
        <collision>
            <origin rpy="0 0 0" xyz="0 0 0" />
            <geometry>
                <cylinder length="0.06" radius="0.005" />
            </geometry>
        </collision>
        <inertial>
            <origin xyz="0 0 0" rpy="0 0 0" />
            <mass value="0.0108" />
            <inertia ixx="3.3075e-06" ixy="0.0" ixz="0.0" iyy="3.3075e-06" iyz="0.0" izz="1.35e-07" />
        </inertial>
    </link>
    <joint name="pole_60_1_joint" type="fixed">
        <parent link="stack_link" />
        <child link="pole_60_1_link" />
        <origin rpy="0 0 0" xyz="-0.06 0.116 0.108" />
    </joint>
    <link name="pole_60_1_link">
        <visual>
            <origin rpy="0 0 0" xyz="0 0 0" />
            <geometry>
                <mesh filename="package://jupiterobot2_description/meshes/stacks/pole_60.stl" scale="0.001 0.001 0.001" />
            </geometry>
            <material name="Grey" />
        </visual>
        <collision>
            <origin rpy="0 0 0" xyz="0 0 0" />
            <geometry>
                <cylinder length="0.06" radius="0.005" />
            </geometry>
        </collision>
        <inertial>
            <origin xyz="0 0 0" rpy="0 0 0" />
            <mass value="0.0108" />
            <inertia ixx="3.3075e-06" ixy="0.0" ixz="0.0" iyy="3.3075e-06" iyz="0.0" izz="1.35e-07" />
        </inertial>
    </link>
    <joint name="pole_60_2_joint" type="fixed">
        <parent link="stack_link" />
        <child link="pole_60_2_link" />
        <origin rpy="0 0 0" xyz="-0.06 -0.116 0.108" />
    </joint>
    <link name="pole_60_2_link">
        <visual>
            <origin rpy="0 0 0" xyz="0 0 0" />
            <geometry>
                <mesh filename="package://jupiterobot2_description/meshes/stacks/pole_60.stl" scale="0.001 0.001 0.001" />
            </geometry>
            <material name="Grey" />
        </visual>
        <collision>
            <origin rpy="0 0 0" xyz="0 0 0" />
            <geometry>
                <cylinder length="0.06" radius="0.005" />
            </geometry>
        </collision>
        <inertial>
            <origin xyz="0 0 0" rpy="0 0 0" />
            <mass value="0.0108" />
            <inertia ixx="3.3075e-06" ixy="0.0" ixz="0.0" iyy="3.3075e-06" iyz="0.0" izz="1.35e-07" />
        </inertial>
    </link>
    <joint name="pole_60_3_joint" type="fixed">
        <parent link="stack_link" />
        <child link="pole_60_3_link" />
        <origin rpy="0 0 0" xyz="0.06 -0.116 0.108" />
    </joint>
    <link name="pole_60_3_link">
        <visual>
            <origin rpy="0 0 0" xyz="0 0 0" />
            <geometry>
                <mesh filename="package://jupiterobot2_description/meshes/stacks/pole_60.stl" scale="0.001 0.001 0.001" />
            </geometry>
            <material name="Grey" />
        </visual>
        <collision>
            <origin rpy="0 0 0" xyz="0 0 0" />
            <geometry>
                <cylinder length="0.06" radius="0.005" />
            </geometry>
        </collision>
        <inertial>
            <origin xyz="0 0 0" rpy="0 0 0" />
            <mass value="0.0108" />
            <inertia ixx="3.3075e-06" ixy="0.0" ixz="0.0" iyy="3.3075e-06" iyz="0.0" izz="1.35e-07" />
        </inertial>
    </link>
    <joint name="plate_1_joint" type="fixed">
        <parent link="stack_link" />
        <child link="plate_1_link" />
        <origin rpy="0 0 0" xyz="0 0 0.138" />
    </joint>
    <link name="plate_1_link">
        <visual>
            <origin rpy="0 0 0" xyz="0 0 0" />
            <geometry>
                <mesh filename="package://jupiterobot2_description/meshes/stacks/plate_1.stl" scale="0.001 0.001 0.001" />
            </geometry>
            <material name="Black" />
        </visual>
        <collision>
            <origin rpy="0 0 0" xyz="0 0 0.003" />
            <geometry>
                <cylinder length="0.006" radius="0.165" />
            </geometry>
        </collision>
        <inertial>
            <origin xyz="0 0 0.003" rpy="0 0 0" />
            <mass value="0.45" />
            <inertia ixx="0.0030641625" ixy="0.0" ixz="0.0" iyy="0.0030641625" iyz="0.0" izz="0.006125625" />
        </inertial>
    </link>
    <joint name="arrow_joint" type="fixed">
        <parent link="plate_1_link" />
        <child link="arrow_link" />
        <origin rpy="0 0 0" xyz="0 0.036 0.006" />
    </joint>
    <link name="arrow_link">
        <visual>
            <origin rpy="0 0 0" xyz="0 0 0" />
            <geometry>
                <mesh filename="package://jupiterobot2_description/meshes/stacks/arrow.stl" scale="0.001 0.001 0.001" />
            </geometry>
            <material name="White" />
        </visual>
        <collision>
            <origin rpy="0 0 0" xyz="0 0 0" />
            <geometry>
                <mesh filename="package://jupiterobot2_description/meshes/stacks/arrow.stl" scale="0.001 0.001 0.001" />
            </geometry>
        </collision>
        <inertial>
            <mass value="0.1" />
            <origin xyz="0 0 0" rpy="0 0 0" />
            <inertia ixx="0.03" iyy="0.03" izz="0.03" ixy="0.0" ixz="0.0" iyz="0.0" />
        </inertial>
    </link>
    <joint name="scan_joint" type="fixed">
        <parent link="plate_1_link" />
        <child link="base_scan" />
        <origin rpy="0 3.14159265359 0" xyz="0 0 -0.04615" />
    </joint>
    <link name="base_scan">
        <visual>
            <origin rpy="0 0 0" xyz="0 0 0" />
            <geometry>
                <mesh filename="package://jupiterobot2_description/meshes/sensors/rplidar.dae" scale="1 1 1" />
            </geometry>
        </visual>
        <collision>
            <origin rpy="0 0 0" xyz="0.01 0 -0.016" />
            <geometry>
                <cylinder length="0.05" radius="0.05" />
            </geometry>
        </collision>
        <inertial>
            <origin xyz="0.01 0 -0.016" rpy="0 0 0" />
            <mass value="0.188" />
            <inertia ixx="0.0001567" ixy="0.0" ixz="0.0" iyy="0.0001567" iyz="0.0" izz="0.000235" />
        </inertial>
    </link>
    <!-- arm_mount -->
    <joint name="arm_mount_joint" type="fixed">
        <parent link="plate_1_link" />
        <child link="arm_mount_link" />
        <origin rpy="0 0 0" xyz="0.134 0 0.006" />
    </joint>
    <link name="arm_mount_link">
        <visual>
            <origin rpy="0 0 0" xyz="0 0 0" />
            <geometry>
                <mesh filename="package://jupiterobot2_description/meshes/stacks/arm_mount.stl" scale="0.001 0.001 0.001" />
            </geometry>
            <material name="DarkGrey" />
        </visual>
        <collision>
            <origin rpy="0 0 0" xyz="-0.013 0 0.0015" />
            <geometry>
                <box size="0.056 0.064 0.003" />
            </geometry>
        </collision>
        <inertial>
            <origin rpy="0 0 0" xyz="-0.013 0 0.0015" />
            <mass value="0.0071" />
            <inertia ixx="2.42879167e-06" ixy="0" ixz="0" iyy="1.86079167e-06" iyz="0" izz="4.278933e-06" />
        </inertial>
    </link>
    <joint name="cables_joint" type="fixed">
        <parent link="plate_1_link" />
        <child link="cables_link" />
        <origin rpy="1.570796326795 0 1.570796326795" xyz="-0.13 0 0" />
    </joint>
    <link name="cables_link">
        <visual>
            <origin rpy="0 0 0" xyz="0 0 0" />
            <geometry>
                <mesh filename="package://jupiterobot2_description/meshes/stacks/cables.stl" scale="0.001 0.001 0.001" />
            </geometry>
            <material name="FlatBlack" />
        </visual>
        <collision>
            <origin rpy="0 0 0" xyz="0 0 0" />
            <geometry>
                <mesh filename="package://jupiterobot2_description/meshes/stacks/cables.stl" scale="0.001 0.001 0.001" />
            </geometry>
        </collision>
        <inertial>
            <mass value="0.1" />
            <origin xyz="0 0 0" rpy="0 0 0" />
            <inertia ixx="0.03" iyy="0.03" izz="0.03" ixy="0.0" ixz="0.0" iyz="0.0" />
        </inertial>
    </link>
    <joint name="pole_200_0_joint" type="fixed">
        <parent link="plate_1_link" />
        <child link="pole_200_0_link" />
        <origin rpy="0 0 0" xyz="-0.05 0.12817 0.106" />
    </joint>
    <link name="pole_200_0_link">
        <visual>
            <origin rpy="0 0 0" xyz="0 0 0" />
            <geometry>
                <mesh filename="package://jupiterobot2_description/meshes/stacks/pole_200.stl" scale="0.001 0.001 0.001" />
            </geometry>
            <material name="Grey" />
        </visual>
        <collision>
            <origin rpy="0 0 0" xyz="0 0 0" />
            <geometry>
                <cylinder length="0.2" radius="0.005" />
            </geometry>
        </collision>
        <inertial>
            <origin xyz="0 0 0" rpy="0 0 0" />
            <mass value="0.0361" />
            <inertia ixx="0.000120559" ixy="0.0" ixz="0.0" iyy="0.000120559" iyz="0.0" izz="4.5125e-07" />
        </inertial>
    </link>
    <joint name="pole_200_1_joint" type="fixed">
        <parent link="plate_1_link" />
        <child link="pole_200_1_link" />
        <origin rpy="0 0 0" xyz="-0.10629 0.09567 0.106" />
    </joint>
    <link name="pole_200_1_link">
        <visual>
            <origin rpy="0 0 0" xyz="0 0 0" />
            <geometry>
                <mesh filename="package://jupiterobot2_description/meshes/stacks/pole_200.stl" scale="0.001 0.001 0.001" />
            </geometry>
            <material name="Grey" />
        </visual>
        <collision>
            <origin rpy="0 0 0" xyz="0 0 0" />
            <geometry>
                <cylinder length="0.2" radius="0.005" />
            </geometry>
        </collision>
        <inertial>
            <origin xyz="0 0 0" rpy="0 0 0" />
            <mass value="0.0361" />
            <inertia ixx="0.000120559" ixy="0.0" ixz="0.0" iyy="0.000120559" iyz="0.0" izz="4.5125e-07" />
        </inertial>
    </link>
    <joint name="pole_200_2_joint" type="fixed">
        <parent link="plate_1_link" />
        <child link="pole_200_2_link" />
        <origin rpy="0 0 0" xyz="-0.10629 -0.09567 0.106" />
    </joint>
    <link name="pole_200_2_link">
        <visual>
            <origin rpy="0 0 0" xyz="0 0 0" />
            <geometry>
                <mesh filename="package://jupiterobot2_description/meshes/stacks/pole_200.stl" scale="0.001 0.001 0.001" />
            </geometry>
            <material name="Grey" />
        </visual>
        <collision>
            <origin rpy="0 0 0" xyz="0 0 0" />
            <geometry>
                <cylinder length="0.2" radius="0.005" />
            </geometry>
        </collision>
        <inertial>
            <origin xyz="0 0 0" rpy="0 0 0" />
            <mass value="0.0361" />
            <inertia ixx="0.000120559" ixy="0.0" ixz="0.0" iyy="0.000120559" iyz="0.0" izz="4.5125e-07" />
        </inertial>
    </link>
    <joint name="pole_200_3_joint" type="fixed">
        <parent link="plate_1_link" />
        <child link="pole_200_3_link" />
        <origin rpy="0 0 0" xyz="-0.05 -0.12817 0.106" />
    </joint>
    <link name="pole_200_3_link">
        <visual>
            <origin rpy="0 0 0" xyz="0 0 0" />
            <geometry>
                <mesh filename="package://jupiterobot2_description/meshes/stacks/pole_200.stl" scale="0.001 0.001 0.001" />
            </geometry>
            <material name="Grey" />
        </visual>
        <collision>
            <origin rpy="0 0 0" xyz="0 0 0" />
            <geometry>
                <cylinder length="0.2" radius="0.005" />
            </geometry>
        </collision>
        <inertial>
            <origin xyz="0 0 0" rpy="0 0 0" />
            <mass value="0.0361" />
            <inertia ixx="0.000120559" ixy="0.0" ixz="0.0" iyy="0.000120559" iyz="0.0" izz="4.5125e-07" />
        </inertial>
    </link>
    <joint name="pipe_200_joint" type="fixed">
        <parent link="plate_1_link" />
        <child link="pipe_200_link" />
        <origin rpy="0 0 0" xyz="-0.13 0 0.106" />
    </joint>
    <link name="pipe_200_link">
        <visual>
            <origin rpy="0 0 0" xyz="0 0 0" />
            <geometry>
                <mesh filename="package://jupiterobot2_description/meshes/stacks/pipe_200.stl" scale="0.001 0.001 0.001" />
            </geometry>
            <material name="FlatBlack" />
        </visual>
        <collision>
            <origin rpy="0 0 0" xyz="0 0 0" />
            <geometry>
                <cylinder length="0.2" radius="0.0125" />
            </geometry>
        </collision>
        <inertial>
            <origin xyz="0 0 0" rpy="0 0 0" />
            <mass value="0.04" />
            <inertia ixx="0.000134896" ixy="0.0" ixz="0.0" iyy="0.000134896" iyz="0.0" izz="3.125e-06" />
        </inertial>
    </link>
    <joint name="plate_3_joint" type="fixed">
        <parent link="plate_1_link" />
        <child link="plate_3_link" />
        <origin rpy="0 0 0" xyz="0 0 0.206" />
    </joint>
    <link name="plate_3_link">
        <visual>
            <origin rpy="0 0 0" xyz="0 0 0" />
            <geometry>
                <mesh filename="package://jupiterobot2_description/meshes/stacks/plate_3.stl" scale="0.001 0.001 0.001" />
            </geometry>
            <material name="Black" />
        </visual>
        <collision>
            <origin rpy="0 0 0" xyz="0 0 0" />
            <geometry>
                <mesh filename="package://jupiterobot2_description/meshes/stacks/plate_3.stl" scale="0.001 0.001 0.001" />
            </geometry>
        </collision>
        <inertial>
            <origin xyz="-0.08 0 0.003" rpy="0 0 0" />
            <!--0.16*0.27*0.006-->
            <mass value="0.152" />
            <inertia ixx="0.000923856" ixy="0.0" ixz="0.0" iyy="0.0003247227" iyz="0.0" izz="0.001247667" />
        </inertial>
    </link>
    <joint name="mic_joint" type="fixed">
        <parent link="plate_3_link" />
        <child link="mic_link" />
        <origin rpy="0 0 0" xyz="0 -0.13466 0.006" />
    </joint>
    <link name="mic_link">
        <visual>
            <origin rpy="0 0 0" xyz="0 0 0" />
            <geometry>
                <mesh filename="package://jupiterobot2_description/meshes/stacks/microphone.stl" scale="0.001 0.001 0.001" />
            </geometry>
            <material name="DarkGrey" />
        </visual>
        <collision>
            <origin rpy="0 0 0" xyz="0 0 0" />
            <geometry>
                <mesh filename="package://jupiterobot2_description/meshes/stacks/microphone.stl" scale="0.001 0.001 0.001" />
            </geometry>
        </collision>
        <inertial>
            <origin xyz="-0.02 0 0.03" rpy="0 0 0" />
            <!--0.04*0.03*0.06-->
            <mass value="0.21" />
            <inertia ixx="7.875e-05" ixy="0.0" ixz="0.0" iyy="9.1e-05" iyz="0.0" izz="4.375e-05" />
        </inertial>
    </link>
    <joint name="estop_joint" type="fixed">
        <parent link="plate_3_link" />
        <child link="estop_link" />
        <origin rpy="0 0 0" xyz="0 0.13466 -0.0381" />
    </joint>
    <link name="estop_link">
        <visual>
            <origin rpy="0 0 0" xyz="0 0 0" />
            <geometry>
                <mesh filename="package://jupiterobot2_description/meshes/stacks/e_stop.stl" scale="0.001 0.001 0.001" />
            </geometry>
            <material name="DarkGrey" />
        </visual>
        <collision>
            <origin rpy="0 0 0" xyz="0 0 0" />
            <geometry>
                <mesh filename="package://jupiterobot2_description/meshes/stacks/e_stop.stl" scale="0.001 0.001 0.001" />
            </geometry>
        </collision>
        <inertial>
            <origin xyz="0 0 0.038" rpy="0 0 0" />
            <!--R0.018*0.0685-->
            <mass value="0.0763" />
            <inertia ixx="3.60151896e-05" ixy="0.0" ixz="0.0" iyy="3.60151896e-05" iyz="0.0" izz="1.23606e-05" />
        </inertial>
    </link>
    <joint name="pole_80_0_joint" type="fixed">
        <parent link="plate_3_link" />
        <child link="pole_80_0_link" />
        <origin rpy="0 0 0" xyz="-0.115 0.05 0.046" />
    </joint>
    <link name="pole_80_0_link">
        <visual>
            <origin rpy="0 0 0" xyz="0 0 0" />
            <geometry>
                <mesh filename="package://jupiterobot2_description/meshes/stacks/pole_80.stl" scale="0.001 0.001 0.001" />
            </geometry>
            <material name="Grey" />
        </visual>
        <collision>
            <origin rpy="0 0 0" xyz="0 0 0" />
            <geometry>
                <cylinder length="0.08" radius="0.005" />
            </geometry>
        </collision>
        <inertial>
            <origin xyz="0 0 0" rpy="0 0 0" />
            <mass value="0.0145" />
            <inertia ixx="7.82395833e-06" ixy="0.0" ixz="0.0" iyy="7.82395833e-06" iyz="0.0" izz="1.8125e-07" />
        </inertial>
    </link>
    <joint name="pole_80_1_joint" type="fixed">
        <parent link="plate_3_link" />
        <child link="pole_80_1_link" />
        <origin rpy="0 0 0" xyz="-0.115 -0.05 0.046" />
    </joint>
    <link name="pole_80_1_link">
        <visual>
            <origin rpy="0 0 0" xyz="0 0 0" />
            <geometry>
                <mesh filename="package://jupiterobot2_description/meshes/stacks/pole_80.stl" scale="0.001 0.001 0.001" />
            </geometry>
            <material name="Grey" />
        </visual>
        <collision>
            <origin rpy="0 0 0" xyz="0 0 0" />
            <geometry>
                <cylinder length="0.08" radius="0.005" />
            </geometry>
        </collision>
        <inertial>
            <origin xyz="0 0 0" rpy="0 0 0" />
            <mass value="0.0145" />
            <inertia ixx="7.82395833e-06" ixy="0.0" ixz="0.0" iyy="7.82395833e-06" iyz="0.0" izz="1.8125e-07" />
        </inertial>
    </link>
    <joint name="monitor_frame_1_joint" type="fixed">
        <parent link="plate_3_link" />
        <child link="monitor_frame_1_link" />
        <origin rpy="0 0 0" xyz="-0.115 0 0.0935" />
    </joint>
    <link name="monitor_frame_1_link">
        <visual>
            <origin rpy="0 0 0" xyz="0 0 0" />
            <geometry>
                <mesh filename="package://jupiterobot2_description/meshes/stacks/monitor_frame.stl" scale="0.001 0.001 0.001" />
            </geometry>
            <material name="DarkGrey" />
        </visual>
        <collision>
            <origin rpy="0 0 0" xyz="0 0 0" />
            <geometry>
                <mesh filename="package://jupiterobot2_description/meshes/stacks/monitor_frame.stl" scale="0.001 0.001 0.001" />
            </geometry>
        </collision>
        <inertial>
            <origin xyz="0 0 0" rpy="0 0 0" />
            <!--0.012*0.112*0.015-->
            <mass value="0.0136" />
            <inertia ixx="1.4471533e-05" ixy="0.0" ixz="0.0" iyy="4.182e-07" iyz="0.0" izz="1.4379733e-05" />
        </inertial>
    </link>
    <joint name="pole_60_4_joint" type="fixed">
        <parent link="pole_80_0_link" />
        <child link="pole_60_4_link" />
        <origin rpy="0 0 0" xyz="0 0 0.085" />
    </joint>
    <link name="pole_60_4_link">
        <visual>
            <origin rpy="0 0 0" xyz="0 0 0" />
            <geometry>
                <mesh filename="package://jupiterobot2_description/meshes/stacks/pole_60.stl" scale="0.001 0.001 0.001" />
            </geometry>
            <material name="Grey" />
        </visual>
        <collision>
            <origin rpy="0 0 0" xyz="0 0 0" />
            <geometry>
                <cylinder length="0.06" radius="0.005" />
            </geometry>
        </collision>
        <inertial>
            <origin xyz="0 0 0" rpy="0 0 0" />
            <mass value="0.0108" />
            <inertia ixx="3.3075e-06" ixy="0.0" ixz="0.0" iyy="3.3075e-06" iyz="0.0" izz="1.35e-07" />
        </inertial>
    </link>
    <joint name="pole_60_5_joint" type="fixed">
        <parent link="pole_80_1_link" />
        <child link="pole_60_5_link" />
        <origin rpy="0 0 0" xyz="0 0 0.085" />
    </joint>
    <link name="pole_60_5_link">
        <visual>
            <origin rpy="0 0 0" xyz="0 0 0" />
            <geometry>
                <mesh filename="package://jupiterobot2_description/meshes/stacks/pole_60.stl" scale="0.001 0.001 0.001" />
            </geometry>
            <material name="Grey" />
        </visual>
        <collision>
            <origin rpy="0 0 0" xyz="0 0 0" />
            <geometry>
                <cylinder length="0.06" radius="0.005" />
            </geometry>
        </collision>
        <inertial>
            <origin xyz="0 0 0" rpy="0 0 0" />
            <mass value="0.0108" />
            <inertia ixx="3.3075e-06" ixy="0.0" ixz="0.0" iyy="3.3075e-06" iyz="0.0" izz="1.35e-07" />
        </inertial>
    </link>
    <joint name="monitor_frame_2_joint" type="fixed">
        <parent link="monitor_frame_1_link" />
        <child link="monitor_frame_2_link" />
        <origin rpy="0 0 0" xyz="0 0 0.075" />
    </joint>
    <link name="monitor_frame_2_link">
        <visual>
            <origin rpy="0 0 0" xyz="0 0 0" />
            <geometry>
                <mesh filename="package://jupiterobot2_description/meshes/stacks/monitor_frame.stl" scale="0.001 0.001 0.001" />
            </geometry>
            <material name="DarkGrey" />
        </visual>
        <collision>
            <origin rpy="0 0 0" xyz="0 0 0" />
            <geometry>
                <mesh filename="package://jupiterobot2_description/meshes/stacks/monitor_frame.stl" scale="0.001 0.001 0.001" />
            </geometry>
        </collision>
        <inertial>
            <origin xyz="0 0 0" rpy="0 0 0" />
            <!--0.012*0.112*0.015-->
            <mass value="0.0136" />
            <inertia ixx="1.4471533e-05" ixy="0.0" ixz="0.0" iyy="4.182e-07" iyz="0.0" izz="1.4379733e-05" />
        </inertial>
    </link>
    <joint name="pole_40_0_joint" type="fixed">
        <parent link="pole_60_4_link" />
        <child link="pole_40_0_link" />
        <origin rpy="0 0 0" xyz="0 0 0.065" />
    </joint>
    <link name="pole_40_0_link">
        <visual>
            <origin rpy="0 0 0" xyz="0 0 0" />
            <geometry>
                <mesh filename="package://jupiterobot2_description/meshes/stacks/pole_40.stl" scale="0.001 0.001 0.001" />
            </geometry>
            <material name="Grey" />
        </visual>
        <collision>
            <origin rpy="0 0 0" xyz="0 0 0" />
            <geometry>
                <cylinder length="0.04" radius="0.005" />
            </geometry>
        </collision>
        <inertial>
            <origin xyz="0 0 0" rpy="0 0 0" />
            <mass value="0.007" />
            <inertia ixx="9.91041667e-07" ixy="0.0" ixz="0.0" iyy="9.91041667e-07" iyz="0.0" izz="8.875e-08" />
        </inertial>
    </link>
    <joint name="pole_40_1_joint" type="fixed">
        <parent link="pole_60_5_link" />
        <child link="pole_40_1_link" />
        <origin rpy="0 0 0" xyz="0 0 0.065" />
    </joint>
    <link name="pole_40_1_link">
        <visual>
            <origin rpy="0 0 0" xyz="0 0 0" />
            <geometry>
                <mesh filename="package://jupiterobot2_description/meshes/stacks/pole_40.stl" scale="0.001 0.001 0.001" />
            </geometry>
            <material name="Grey" />
        </visual>
        <collision>
            <origin rpy="0 0 0" xyz="0 0 0" />
            <geometry>
                <cylinder length="0.04" radius="0.005" />
            </geometry>
        </collision>
        <inertial>
            <origin xyz="0 0 0" rpy="0 0 0" />
            <mass value="0.007" />
            <inertia ixx="9.91041667e-07" ixy="0.0" ixz="0.0" iyy="9.91041667e-07" iyz="0.0" izz="8.875e-08" />
        </inertial>
    </link>
    <!-- head_mount -->
    <joint name="head_mount_joint" type="fixed">
        <parent link="monitor_frame_2_link" />
        <child link="head_mount_link" />
        <origin rpy="0 0 0" xyz="0 0 0.0475" />
    </joint>
    <link name="head_mount_link">
        <visual>
            <origin rpy="0 0 0" xyz="0 0 0" />
            <geometry>
                <mesh filename="package://jupiterobot2_description/meshes/stacks/head_mount.stl" scale="0.001 0.001 0.001" />
            </geometry>
            <material name="DarkGrey" />
        </visual>
        <collision>
            <origin rpy="0 0 0" xyz="0 0 0.012" />
            <geometry>
                <box size="0.05 0.13 0.024" />
            </geometry>
        </collision>
        <inertial>
            <origin rpy="0 0 0" xyz="0 0 0.005" />
            <!--0.04*0.12*0.01-->
            <mass value="0.0205" />
            <inertia ixx="2.4770833e-05" ixy="0" ixz="0" iyy="2.9041667e-06" iyz="0" izz="2.7333e-05" />
        </inertial>
    </link>
    <joint name="monitor_joint" type="fixed">
        <parent link="monitor_frame_2_link" />
        <child link="monitor_link" />
        <origin rpy="0 0 0" xyz="0.0405 0 -0.046" />
    </joint>
    <link name="monitor_link">
        <visual>
            <origin rpy="0 0 0" xyz="0 0 0" />
            <geometry>
                <mesh filename="package://jupiterobot2_description/meshes/stacks/monitor.stl" scale="0.001 0.001 0.001" />
            </geometry>
            <material name="FlatBlack" />
        </visual>
        <collision>
            <origin rpy="0 0 0" xyz="0 0 0" />
            <geometry>
                <mesh filename="package://jupiterobot2_description/meshes/stacks/monitor.stl" scale="0.001 0.001 0.001" />
            </geometry>
        </collision>
        <inertial>
            <origin xyz="-0.013 0 0.005" rpy="0 0 0" />
            <!--0.026*0.2465*0.167-->
            <mass value="0.48" />
            <inertia ixx="0.00354605" ixy="0.0" ixz="0.0" iyy="0.0011426" iyz="0.0" izz="0.00245753" />
        </inertial>
    </link>
    <joint name="screen_joint" type="fixed">
        <parent link="monitor_link" />
        <child link="screen_link" />
        <origin rpy="0 0 0" xyz="-0.0025 0 0" />
    </joint>
    <link name="screen_link">
        <visual>
            <origin rpy="0 0 0" xyz="0 0 0" />
            <geometry>
                <mesh filename="package://jupiterobot2_description/meshes/stacks/screen.stl" scale="0.001 0.001 0.001" />
            </geometry>
            <material name="White" />
        </visual>
        <collision>
            <origin rpy="0 0 0" xyz="0 0 0" />
            <geometry>
                <mesh filename="package://jupiterobot2_description/meshes/stacks/screen.stl" scale="0.001 0.001 0.001" />
            </geometry>
        </collision>
        <inertial>
            <mass value="0.1" />
            <origin xyz="0 0 0" rpy="0 0 0" />
            <inertia ixx="0.03" iyy="0.03" izz="0.03" ixy="0.0" ixz="0.0" iyz="0.0" />
        </inertial>
    </link>
    <transmission name="trans_gripper_link_joint">
        <type>transmission_interface/SimpleTransmission</type>
        <joint name="gripper_link_joint">
            <hardwareInterface>hardware_interface/EffortJointInterface</hardwareInterface>
        </joint>
        <actuator name="gripper_link_joint_motor">
            <hardwareInterface>hardware_interface/EffortJointInterface</hardwareInterface>
            <mechanicalReduction>1</mechanicalReduction>
        </actuator>
    </transmission>
    <transmission name="trans_wheel_left_joint">
        <type>transmission_interface/SimpleTransmission</type>
        <joint name="wheel_left_joint">
            <hardwareInterface>hardware_interface/EffortJointInterface</hardwareInterface>
        </joint>
        <actuator name="wheel_left_joint_motor">
            <hardwareInterface>hardware_interface/EffortJointInterface</hardwareInterface>
            <mechanicalReduction>1</mechanicalReduction>
        </actuator>
    </transmission>
    <transmission name="trans_wheel_right_joint">
        <type>transmission_interface/SimpleTransmission</type>
        <joint name="wheel_right_joint">
            <hardwareInterface>hardware_interface/EffortJointInterface</hardwareInterface>
        </joint>
        <actuator name="wheel_right_joint_motor">
            <hardwareInterface>hardware_interface/EffortJointInterface</hardwareInterface>
            <mechanicalReduction>1</mechanicalReduction>
        </actuator>
    </transmission>
</robot>

